Workbook

Sheet Sheet1
A2: Tester note: Use plain user language. Avoid technical terms (token, endpoint, route, console) in test steps. | B2: Write tests using UI words testers can see: screen title, button, table, card, menu, message. | C2: Run in order: P0 first, then P1, then P2. | D2: Release gate: do all P0 tests first and resolve blockers before running P1/P2.
A3: AREA | B3: ID | C3: Page | D3: step# | E3: Test Step | F3: Expected Result | G3: Expected Status | H3: Actual Result | I3: Priority Level | J3: Solution | K3: Fix Applied | L3: Role Scope | M3: Traceability ID | N3: Bug Ticket | O3: Code Path Default | P3: Execution Tier
A4: Login Page - Authenticate users securely and establish/terminate application sessions.
B5: 1.01 | C5: Login | D5: 1 | E5: Navigate to the login URL | F5: Page loads with Username and Password fields | G5: Not Tested | I5: N/A | L5: User | M5: TRC-1.01-LOGIN | P5: P0 - Critical Path
B6: 1.02 | C6: Login | D6: 2 | E6: Enter valid credentials and click "Login" | F6: User is redirected to the Dashboard/Home page | G6: Not Tested | I6: N/A | L6: User | M6: TRC-1.02-LOGIN | P6: P0 - Critical Path
B7: 1.03 | C7: Login | D7: 3 | E7: Enter valid username but incorrect password | F7: Error message: "Invalid credentials" (or similar) | G7: Not Tested | I7: N/A | L7: User | M7: TRC-1.03-LOGIN | P7: P0 - Critical Path
B8: 1.04 | C8: Login | D8: 4 | E8: Leave both fields empty and click "Login" | F8: Browser or App displays "Required Field" validation | G8: Not Tested | I8: N/A | L8: User | M8: TRC-1.04-LOGIN | P8: P0 - Critical Path
B9: 1.05 | C9: Login | D9: 5 | E9: Enter an unregistered email/username | F9: Error message: "User does not exist" | G9: Not Tested | I9: N/A | L9: User | M9: TRC-1.05-LOGIN | P9: P0 - Critical Path
B10: 1.06 | C10: Session | D10: 1 | E10: Log in successfully, then click "Logout" | F10: User is redirected to login; back button doesn't re-log in | G10: Not Tested | I10: N/A | L10: User | M10: TRC-1.06-SESSION | P10: P0 - Critical Path
B11: 1.07 | C11: Session | D11: 2 | E11: Close browser tab without logging out and reopen | F11: User should remain logged in (if 'Remember Me' is active) | G11: Not Tested | I11: N/A | L11: User | M11: TRC-1.07-SESSION | P11: P0 - Critical Path
B12: 1.08 | C12: Security | D12: 3 | E12: Try to access Dashboard URL directly without logging in | F12: System redirects user back to the Login page | G12: Not Tested | I12: N/A | L12: User | M12: TRC-1.08-SECURITY | P12: P0 - Critical Path
A15: Home Page - League overview hub with standings, navigation, and assistant entry points.
B16: 2.01 | C16: Navigation | D16: 1 | E16: Click the hamburger menu icon | F16: Sidebar menu expands and is visible | G16: Not Tested | I16: N/A | L16: User | M16: TRC-2.01-NAVIGATION | P16: P2 - Extended Coverage
B17: 2.02 | C17: Navigation | D17: 2 | E17: Click the hamburger icon (or 'X') while expanded | F17: Sidebar menu collapses and is hidden | G17: Not Tested | I17: N/A | L17: User | M17: TRC-2.02-NAVIGATION | P17: P2 - Extended Coverage
B18: 2.03 | C18: UI/UX | D18: 1 | E18: Toggle the Dark/Light mode switch | F18: Theme colors update immediately across the UI | G18: Not Tested | I18: N/A | L18: User | M18: TRC-2.03-UI-UX | P18: P2 - Extended Coverage
B19: 2.04 | C19: UI/UX | D19: 2 | E19: Refresh page after changing theme | F19: Theme preference is persisted (Dark or Light) | G19: Not Tested | I19: N/A | L19: User | M19: TRC-2.04-UI-UX | P19: P2 - Extended Coverage
B20: 2.05 | C20: Teams | D20: 1 | E20: Click on any Team Name or Logo in the list | F20: User is redirected to that team's "Locker Room" page | G20: Not Tested | I20: N/A | L20: User | M20: TRC-2.05-TEAMS | P20: P2 - Extended Coverage
B21: 2.06 | C21: Teams | D21: 2 | E21: Click on the User's own team link | F21: User is redirected to their personal "Locker Room" | G21: Not Tested | I21: N/A | L21: User | M21: TRC-2.06-TEAMS | P21: P2 - Extended Coverage
B22: 2.07 | C22: Teams | D22: 1 | E22: Locate the League Standings table | F22: Table displays: Division, W/L/T, PF, and PA | G22: Not Tested | I22: N/A | L22: User | M22: TRC-2.07-TEAMS | P22: P2 - Extended Coverage
B23: 2.08 | C23: Teams | D23: 2 | E23: Verify data accuracy for "Team Nick Grant" | F23: Stats match the underlying database/API values | G23: Not Tested | I23: N/A | L23: User | M23: TRC-2.08-TEAMS | P23: P2 - Extended Coverage
B24: 2.09 | C24: Teams | D24: 1 | E24: Sort table by "PF" (Points For) | F24: Table reorders correctly from highest to lowest | G24: Not Tested | I24: N/A | L24: User | M24: TRC-2.09-TEAMS | P24: P2 - Extended Coverage
B25: 2.10 | C25: Content | D25: 1 | E25: Locate the "League News" section | F25: News feed displays latest league updates/posts | G25: Not Tested | I25: N/A | L25: User | M25: TRC-2.10-CONTENT | P25: P2 - Extended Coverage
B26: 2.11 | C26: AI/Chat | D26: 1 | E26: Click the Chat Assistant icon/button | F26: Chat interface expands/opens for user input | G26: Not Tested | I26: N/A | L26: User | M26: TRC-2.11-AI-CHAT | P26: P2 - Extended Coverage
B27: 2.12 | C27: AI/Chat | D27: 2 | E27: Click the collapse/close button on Chat | F27: Chat interface minimizes or hides from view | G27: Not Tested | I27: N/A | L27: User | M27: TRC-2.12-AI-CHAT | P27: P2 - Extended Coverage
... B32: 2.17 | C32: AI/Chat | D32: 5 | E32: Close chat and reopen | F32: Chat history persists (if implemented) | G32: Not Tested | I32: N/A | L32: User | M32: TRC-2.17-AI-CHAT | P32: P2 - Extended Coverage
A35: My Team Page - Team owner workspace for lineup decisions, roster changes, and trade actions.
B36: 3.01 | C36: My Team | D36: 1 | E36: Click Hamburger / Dark Mode / Chat | F36: UI components mirror Home Page behavior | G36: Not Tested | I36: N/A | L36: User | M36: TRC-3.01-MY-TEAM | P36: P2 - Extended Coverage
B37: 3.02 | C37: My Team | D37: 1 | E37: Ask Chat: "Who should I start this week?" | F37: AI analyzes roster/matchups and gives a suggestion | G37: Not Tested | I37: N/A | L37: User | M37: TRC-3.02-MY-TEAM | P37: P2 - Extended Coverage
B38: 3.03 | C38: Lineup | D38: 1 | E38: Toggle between "Recommend" and "Actual" views | F38: View shifts between AI-suggested and saved lineup | G38: Not Tested | I38: N/A | L38: User | M38: TRC-3.03-LINEUP | P38: P2 - Extended Coverage
B39: 3.04 | C39: Lineup | D39: 1 | E39: Select a different week from the dropdown | F39: Roster/Matchups update to reflect selected week | G39: Not Tested | I39: N/A | L39: User | M39: TRC-3.04-LINEUP | P39: P2 - Extended Coverage
B40: 3.05 | C40: Edit | D40: 1 | E40: Swap a Bench player with a Starter | F40: Position labels update; visual swap occurs | G40: Not Tested | I40: N/A | L40: User | M40: TRC-3.05-EDIT | P40: P2 - Extended Coverage
B41: 3.06 | C41: Edit | D41: 1 | E41: Move a player to a different week's lineup | F41: Change persists when navigating back to that week | G41: Not Tested | I41: N/A | L41: User | M41: TRC-3.06-EDIT | P41: P2 - Extended Coverage
B42: 3.07 | C42: Edit | D42: 1 | E42: Move Bench player to Taxi Squad (and vice versa) | F42: Player moves to/from the designated Taxi section | G42: Not Tested | I42: N/A | L42: User | M42: TRC-3.07-EDIT | P42: P2 - Extended Coverage
B43: 3.08 | C43: Edit | D43: 1 | E43: Exceed roster limit / invalid position start | F43: UI shows Red validation warning per Commish rules | G43: Not Tested | I43: N/A | L43: User | M43: TRC-3.08-EDIT | P43: P2 - Extended Coverage
B44: 3.09 | C44: Edit | D44: 1 | E44: Arrange a legal lineup | F44: UI shows Green validation; "Submit" is enabled | G44: Not Tested | I44: N/A | L44: User | M44: TRC-3.09-EDIT | P44: P0 - Critical Path
B45: 3.10 | C45: Edit | D45: 2 | E45: Click "Submit Roster" | F45: Success message appears; changes save to DB | G45: Not Tested | I45: N/A | L45: User | M45: TRC-3.10-EDIT | P45: P0 - Critical Path
B46: 3.11 | C46: Trade | D46: 1 | E46: Select an owner to trade with | F46: Both teams' rosters load side-by-side | G46: Not Tested | I46: N/A | L46: User | M46: TRC-3.11-TRADE | P46: P2 - Extended Coverage
B47: 3.12 | C47: Trade | D47: 1 | E47: Select players and add/request Draft Dollars | F47: Trade summary updates with selected assets | G47: Not Tested | I47: N/A | L47: User | M47: TRC-3.12-TRADE | P47: P2 - Extended Coverage
... B49: 3.14 | C49: Keepers | D49: 1 | E49: Select a player to keep | F49: [Known Issue] Verify if selection saves/fails | G49: Not Tested | I49: N/A | L49: User | M49: TRC-3.14-KEEPERS | P49: P2 - Extended Coverage
A52: Match-up Page - Weekly head-to-head views and Game Center details for matchup outcomes.
...

Sheet Dropdown_Lists
A1: Not Tested | B1: High | C1: Yes | D1: User | E1: New | F1: Critical | G1: ExecutionTier
A2: In Progress | B2: Medium | C2: No | D2: Commissioner | E2: Triaged | F2: High | G2: P0 - Critical Path
A3: Pass | B3: Low | C3: Partial | D3: Site Admin | E3: In Progress | F3: Medium | G3: P1 - Core Regression
A4: Fail | B4: N/A | C4: N/A | D4: Mixed | E4: Fixed | F4: Low | G4: P2 - Extended Coverage
A5: Blocked | E5: Retest
E6: Closed
E7: Deferred

Sheet Defect_Rollup
A1: Master Defect ID | B1: Source Test ID | C1: Traceability ID | D1: Summary | E1: Rollup Status | F1: Severity | G1: Priority | H1: Environment | I1: Role Scope | J1: Bug Ticket | K1: Area/Page | L1: Candidate Code Path | M1: Repro Steps | N1: Expected Result | O1: Actual Result | P1: Evidence Link | Q1: Owner | R1: Notes | S1: Date Reported | T1: Last Updated | V1: Roll-up Metrics
H2: CERT | L2: =IFERROR(_xludf.XLOOKUP(C2,CodePath_Defaults!A:A,CodePath_Defaults!D:D,""),IFERROR(_xludf.XLOOKUP(B2,CodePath_Defaults!B:B,CodePath_Defaults!D:D,""),"")) | T2: 2026-03-07 | V2: Total Defects | W2: =COUNTIF(A2:A2000,"<>") -> 0
L3: =IFERROR(_xludf.XLOOKUP(C3,CodePath_Defaults!A:A,CodePath_Defaults!D:D,""),IFERROR(_xludf.XLOOKUP(B3,CodePath_Defaults!B:B,CodePath_Defaults!D:D,""),"")) | T3: 2026-03-07 | V3: Open Defects | W3: =SUM(COUNTIF(E2:E2000,{"New","Triaged","In Progress","Retest"})) -> 0
L4: =IFERROR(_xludf.XLOOKUP(C4,CodePath_Defaults!A:A,CodePath_Defaults!D:D,""),IFERROR(_xludf.XLOOKUP(B4,CodePath_Defaults!B:B,CodePath_Defaults!D:D,""),"")) | T4: 2026-03-07 | V4: Closed Defects | W4: =COUNTIF(E2:E2000,"Closed") -> 0
L5: =IFERROR(_xludf.XLOOKUP(C5,CodePath_Defaults!A:A,CodePath_Defaults!D:D,""),IFERROR(_xludf.XLOOKUP(B5,CodePath_Defaults!B:B,CodePath_Defaults!D:D,""),"")) | T5: 2026-03-07 | V5: Deferred Defects | W5: =COUNTIF(E2:E2000,"Deferred") -> 0
L6: =IFERROR(_xludf.XLOOKUP(C6,CodePath_Defaults!A:A,CodePath_Defaults!D:D,""),IFERROR(_xludf.XLOOKUP(B6,CodePath_Defaults!B:B,CodePath_Defaults!D:D,""),"")) | T6: 2026-03-07 | V6: Critical Severity | W6: =COUNTIF(F2:F2000,"Critical") -> 0
L7: =IFERROR(_xludf.XLOOKUP(C7,CodePath_Defaults!A:A,CodePath_Defaults!D:D,""),IFERROR(_xludf.XLOOKUP(B7,CodePath_Defaults!B:B,CodePath_Defaults!D:D,""),"")) | T7: 2026-03-07 | V7: High Severity | W7: =COUNTIF(F2:F2000,"High") -> 0
L8: =IFERROR(_xludf.XLOOKUP(C8,CodePath_Defaults!A:A,CodePath_Defaults!D:D,""),IFERROR(_xludf.XLOOKUP(B8,CodePath_Defaults!B:B,CodePath_Defaults!D:D,""),"")) | T8: 2026-03-07 | V8: Medium Severity | W8: =COUNTIF(F2:F2000,"Medium") -> 0
L9: =IFERROR(_xludf.XLOOKUP(C9,CodePath_Defaults!A:A,CodePath_Defaults!D:D,""),IFERROR(_xludf.XLOOKUP(B9,CodePath_Defaults!B:B,CodePath_Defaults!D:D,""),"")) | T9: 2026-03-07 | V9: Low Severity | W9: =COUNTIF(F2:F2000,"Low") -> 0
L10: =IFERROR(_xludf.XLOOKUP(C10,CodePath_Defaults!A:A,CodePath_Defaults!D:D,""),IFERROR(_xludf.XLOOKUP(B10,CodePath_Defaults!B:B,CodePath_Defaults!D:D,""),"")) | T10: 2026-03-07 | V10: CERT Tagged | W10: =COUNTIF(H2:H2000,"CERT") -> 1
L11: =IFERROR(_xludf.XLOOKUP(C11,CodePath_Defaults!A:A,CodePath_Defaults!D:D,""),IFERROR(_xludf.XLOOKUP(B11,CodePath_Defaults!B:B,CodePath_Defaults!D:D,""),"")) | T11: 2026-03-07
L12: =IFERROR(_xludf.XLOOKUP(C12,CodePath_Defaults!A:A,CodePath_Defaults!D:D,""),IFERROR(_xludf.XLOOKUP(B12,CodePath_Defaults!B:B,CodePath_Defaults!D:D,""),"")) | T12: 2026-03-07
L13: =IFERROR(_xludf.XLOOKUP(C13,CodePath_Defaults!A:A,CodePath_Defaults!D:D,""),IFERROR(_xludf.XLOOKUP(B13,CodePath_Defaults!B:B,CodePath_Defaults!D:D,""),"")) | T13: 2026-03-07
L14: =IFERROR(_xludf.XLOOKUP(C14,CodePath_Defaults!A:A,CodePath_Defaults!D:D,""),IFERROR(_xludf.XLOOKUP(B14,CodePath_Defaults!B:B,CodePath_Defaults!D:D,""),"")) | T14: 2026-03-07
L15: =IFERROR(_xludf.XLOOKUP(C15,CodePath_Defaults!A:A,CodePath_Defaults!D:D,""),IFERROR(_xludf.XLOOKUP(B15,CodePath_Defaults!B:B,CodePath_Defaults!D:D,""),"")) | T15: 2026-03-07
L16: =IFERROR(_xludf.XLOOKUP(C16,CodePath_Defaults!A:A,CodePath_Defaults!D:D,""),IFERROR(_xludf.XLOOKUP(B16,CodePath_Defaults!B:B,CodePath_Defaults!D:D,""),"")) | T16: 2026-03-07
L17: =IFERROR(_xludf.XLOOKUP(C17,CodePath_Defaults!A:A,CodePath_Defaults!D:D,""),IFERROR(_xludf.XLOOKUP(B17,CodePath_Defaults!B:B,CodePath_Defaults!D:D,""),"")) | T17: 2026-03-07
L18: =IFERROR(_xludf.XLOOKUP(C18,CodePath_Defaults!A:A,CodePath_Defaults!D:D,""),IFERROR(_xludf.XLOOKUP(B18,CodePath_Defaults!B:B,CodePath_Defaults!D:D,""),"")) | T18: 2026-03-07
L19: =IFERROR(_xludf.XLOOKUP(C19,CodePath_Defaults!A:A,CodePath_Defaults!D:D,""),IFERROR(_xludf.XLOOKUP(B19,CodePath_Defaults!B:B,CodePath_Defaults!D:D,""),"")) | T19: 2026-03-07
L20: =IFERROR(_xludf.XLOOKUP(C20,CodePath_Defaults!A:A,CodePath_Defaults!D:D,""),IFERROR(_xludf.XLOOKUP(B20,CodePath_Defaults!B:B,CodePath_Defaults!D:D,""),"")) | T20: 2026-03-07
L21: =IFERROR(_xludf.XLOOKUP(C21,CodePath_Defaults!A:A,CodePath_Defaults!D:D,""),IFERROR(_xludf.XLOOKUP(B21,CodePath_Defaults!B:B,CodePath_Defaults!D:D,""),"")) | T21: 2026-03-07
L22: =IFERROR(_xludf.XLOOKUP(C22,CodePath_Defaults!A:A,CodePath_Defaults!D:D,""),IFERROR(_xludf.XLOOKUP(B22,CodePath_Defaults!B:B,CodePath_Defaults!D:D,""),"")) | T22: 2026-03-07
... L2000: =IFERROR(_xludf.XLOOKUP(C2000,CodePath_Defaults!A:A,CodePath_Defaults!D:D,""),IFERROR(_xludf.XLOOKUP(B2000,CodePath_Defaults!B:B,CodePath_Defaults!D:D,""),"")) | T2000: 2026-03-07

Sheet CodePath_Defaults
A1: Traceability ID | B1: Source Test ID | C1: Area/Page | D1: Code Path Default | E1: Role Scope
A2: TRC-1.01-LOGIN | B2: 1.01 | C2: Login | E2: User
A3: TRC-1.02-LOGIN | B3: 1.02 | C3: Login | E3: User
A4: TRC-1.03-LOGIN | B4: 1.03 | C4: Login | E4: User
A5: TRC-1.04-LOGIN | B5: 1.04 | C5: Login | E5: User
A6: TRC-1.05-LOGIN | B6: 1.05 | C6: Login | E6: User
A7: TRC-1.06-SESSION | B7: 1.06 | C7: Session | E7: User
A8: TRC-1.07-SESSION | B8: 1.07 | C8: Session | E8: User
A9: TRC-1.08-SECURITY | B9: 1.08 | C9: Security | E9: User
A10: TRC-2.01-NAVIGATION | B10: 2.01 | C10: Navigation | E10: User
A11: TRC-2.02-NAVIGATION | B11: 2.02 | C11: Navigation | E11: User
A12: TRC-2.03-UI-UX | B12: 2.03 | C12: UI/UX | E12: User
A13: TRC-2.04-UI-UX | B13: 2.04 | C13: UI/UX | E13: User
... A64: TRC-TEST-OPS-USABILITY-5.08 | B64: 5.08 | C64: Usability | E64: User
A65: TRC-FE-PAGE-6.01 | B65: 6.01 | C65: Page:ManageCommissioners | D65: frontend/src/pages/admin/ManageCommissioners.jsx | E65: Site Admin
A66: TRC-FE-PAGE-6.02 | B66: 6.02 | C66: Page:ManageCommissioners | D66: frontend/src/pages/admin/ManageCommissioners.jsx | E66: Site Admin
A67: TRC-FE-PAGE-6.03 | B67: 6.03 | C67: Page:SiteAdmin | D67: frontend/src/pages/admin/SiteAdmin.jsx | E67: Site Admin
A68: TRC-FE-PAGE-6.04 | B68: 6.04 | C68: Page:SiteAdmin | D68: frontend/src/pages/admin/SiteAdmin.jsx | E68: Site Admin
A69: TRC-FE-PAGE-6.05 | B69: 6.05 | C69: Page:AnalyticsDashboard | D69: frontend/src/pages/Analytics/AnalyticsDashboard.jsx | E69: User
A70: TRC-FE-PAGE-6.06 | B70: 6.06 | C70: Page:AnalyticsDashboard | D70: frontend/src/pages/Analytics/AnalyticsDashboard.jsx | E70: User
A71: TRC-FE-PAGE-6.07 | B71: 6.07 | C71: Page:BugReport | D71: frontend/src/pages/BugReport.jsx | E71: User
A72: TRC-FE-PAGE-6.08 | B72: 6.08 | C72: Page:BugReport | D72: frontend/src/pages/BugReport.jsx | E72: User
A73: TRC-FE-PAGE-6.09 | B73: 6.09 | C73: Page:CommishAdmin | D73: frontend/src/pages/commissioner/CommishAdmin.jsx | E73: Commissioner
A74: TRC-FE-PAGE-6.10 | B74: 6.10 | C74: Page:CommishAdmin | D74: frontend/src/pages/commissioner/CommishAdmin.jsx | E74: Commissioner
A75: TRC-FE-PAGE-6.11 | B75: 6.11 | C75: Page:CommissionerDashboard | D75: frontend/src/pages/commissioner/CommissionerDashboard.jsx | E75: Commissioner
A76: TRC-FE-PAGE-6.12 | B76: 6.12 | C76: Page:CommissionerDashboard | D76: frontend/src/pages/commissioner/CommissionerDashboard.jsx | E76: Commissioner
... A175: TRC-FE-COMP-7.43 | B175: 7.43 | C175: Component:BracketAccordion | D175: frontend/src/pages/home/components/BracketAccordion.jsx | E175: User
